Workbook

Sheet UNILAB - CUSTOS
A1: Descrição | B1: valor
A2: 2,5 HEXANODIONA, URINA ISOLADA | B2: 17.7
A3: 25-HIDROXI VITAMINA D | B3: 19.5
A4: ACETONA | B4: 55
A5: ACETONA - INICIO DE JORNADA DE TRABALHO | B5: 22
A6: ACETONA, URINA ISOLADA | B6: 22
A7: ACIDO 2 TIO TIAZOLIDINA | B7: 280
A8: ÁCIDO BUTOXIACÉTICO | B8: 310
A9: ACIDO DELTA AMINO LEVULINICO, URINA ISOLADA | B9: 14
A10: ACIDO FENILGLIOXILICO | B10: 34
A11: ACIDO FOLICO | B11: 28
A12: ACIDO FOLICO - POS FILTRO | B12: 15
A13: ACIDO FOLICO - POS HEMODIALISE | B13: 28
... A97: COLINESTERASE PLASMATICA | B97: 4.5
A98: COPROCULTURA | B98: a
A99: COPROCULTURA (EMPRESAS) | B99: 13.5
A100: COPROCULTURA, EMPRESAS | B100: 13.5
A101: CORONAVÍRUS 2019 (SARS-CoV-2), ANTÍGENOS | B101: 80
A102: CORONAVÍRUS 2019 (SARS-CoV-2), ANTÍGENOS - BOSCH | B102: 80
A103: CORTISOL | B103: 20
A104: CORTISOL - DILUIÇÃO | B104: 20
A105: CREATINA SERICA | B105: 22
A106: CREATININA SERICA | B106: 2.7
A107: CREATININA SERICA - NEFRO | B107: 2.7
A108: CREATININA, URINA 12 HORAS | B108: 7
A109: CREATININA, URINA 24 HORAS | B109: 7
A110: CREATININA, URINA ISOLADA | B110: 7
... A360: ZINCO PROTOPORFIRINA | B360: 39

Sheet UNILAB - MAIS VENDIDOS
B1: CENTRO MÉDICO INTEGRADO 2026
B2: UNILAB - EXAMES LABORATORIAIS
B3: EXAMES MAIS UTILIZADOS
B4: QTDE | C4: MNEMÔNICO | D4: PROCEDIMENTO | E4: VALOR
B5: 1 | C5: ACFOL | D5: ÁCIDO FÓLICO | E5: ='UNILAB - RELATÓRIO VENDAS'!E6 -> 47.6
B6: 2 | C6: HIPURIS | D6: ÁCIDO HIPÚRICO | E6: ='UNILAB - RELATÓRIO VENDAS'!E8 -> 19
B7: 3 | C7: METHURIS | D7: ÁCIDO METIL HIPÚRICO | E7: ='UNILAB - RELATÓRIO VENDAS'!E10 -> 19
B8: 4 | C8: ACUR | D8: ÁCIDO ÚRICO | E8: ='UNILAB - RELATÓRIO VENDAS'!E11 -> 6
B9: 5 | C9: CA | D9: CÁLCIO | E9: ='UNILAB - RELATÓRIO VENDAS'!E28 -> 7
B10: 6 | C10: COL | D10: COLESTEROL TOTAL | E10: ='UNILAB - RELATÓRIO VENDAS'!E32 -> 24.5
B11: 7 | C11: COLTF | D11: COLESTEROL TOTAL E FRAÇÕES | E11: ='UNILAB - RELATÓRIO VENDAS'!E33 -> 58
B12: 8 | C12: COPRO | D12: COPROCULTURA | E12: ='UNILAB - RELATÓRIO VENDAS'!E34 -> 23
B13: 9 | C13: CPK | D13: CPK | E13: ='UNILAB - RELATÓRIO VENDAS'!E38 -> 12.3
B14: 10 | C14: CRE | D14: CREATININA | E14: ='UNILAB - RELATÓRIO VENDAS'!E37 -> 6
B15: 11 | C15: FAN | D15: FATOR ANTI NUCLEO | E15: ='UNILAB - RELATÓRIO VENDAS'!E53 -> 34
B16: 12 | C16: FREUM | D16: FATOR REUMATOIDE | E16: ='UNILAB - RELATÓRIO VENDAS'!E54 -> 30.6
B17: 13 | C17: FERR | D17: FERRITINA | E17: ='UNILAB - RELATÓRIO VENDAS'!E56 -> 59.5
B18: 14 | C18: FE | D18: FERRO | E18: ='UNILAB - RELATÓRIO VENDAS'!E57 -> 13
B19: 15 | C19: GLI | D19: GLICOSE | E19: ='UNILAB - RELATÓRIO VENDAS'!E66 -> 6
B20: 16 | C20: HDL | D20: HDL | E20: ='UNILAB - RELATÓRIO VENDAS'!E69 -> 24.5
B21: 17 | C21: HBA1C | D21: HEMOGLOBINA GLICADA | E21: 23
B22: 18 | C22: HEMO | D22: HEMOGRAMA COMPLETO | E22: ='UNILAB - RELATÓRIO VENDAS'!E72 -> 13
B23: 19 | C23: VHS | D23: HEMOSSEDIMENTAÇÃO | E23: ='UNILAB - RELATÓRIO VENDAS'!E73 -> 8.5
B24: 20 | C24: POT | D24: K (POTASSIO) | E24: ='UNILAB - RELATÓRIO VENDAS'!E116 -> 6
B25: 21 | C25: MAG | D25: MAGNESIO | E25: ='UNILAB - RELATÓRIO VENDAS'!E103 -> 12
B26: 22 | C26: SOD | D26: NA (SODIO) | E26: ='UNILAB - RELATÓRIO VENDAS'!E136 -> 6
B27: 23 | C27: NS1 | D27: NS1 TESTE RAPIDO | E27: ='UNILAB - RELATÓRIO VENDAS'!E112 -> 68
B28: 24 | C28: PROTO | D28: PROTOPARASITOLOGICO | E28: ='UNILAB - RELATÓRIO VENDAS'!E122 -> 7.5
B29: 25 | C29: PSAT | D29: PSA | E29: ='UNILAB - RELATÓRIO VENDAS'!E14 -> 38
B30: 26 | C30: PTHI | D30: PTHI | E30: ='UNILAB - RELATÓRIO VENDAS'!E114 -> 85
B31: 27 | C31: SGOCFEZ | D31: SANGUE OCULTO NAS FEZES | E31: ='UNILAB - RELATÓRIO VENDAS'!E134 -> 12.5
B32: 28 | C32: T4 | D32: T4 TOTAL | E32: ='UNILAB - RELATÓRIO VENDAS'!E139 -> 23.8
B33: 29 | C33: T4L | D33: T4L LIVRE | E33: ='UNILAB - RELATÓRIO VENDAS'!E140 -> 24
B34: 30 | C34: TESTL | D34: TESTORONA LIVRE | E34: ='UNILAB - RELATÓRIO VENDAS'!E144 -> 39.1
B35: 31 | C35: TESTT | D35: TESTOSTERONA TOTAL | E35: ='UNILAB - RELATÓRIO VENDAS'!E145 -> 34
B36: 32 | C36: TGO | D36: TRANSAMINASE OXALACETICA | E36: ='UNILAB - RELATÓRIO VENDAS'!E149 -> 6
B37: 33 | C37: TGP | D37: TRANSAMINASE PIRUVICA | E37: ='UNILAB - RELATÓRIO VENDAS'!E150 -> 6
B38: 34 | C38: TGL | D38: TRIGLICERIDES | E38: ='UNILAB - RELATÓRIO VENDAS'!E151 -> 8.5
B39: 35 | C39: TROPO | D39: TROPOTONINA | E39: ='UNILAB - RELATÓRIO VENDAS'!E152 -> 98.6
B40: 36 | C40: TSH | D40: TSH ULTRA SENSIVEL | E40: ='UNILAB - RELATÓRIO VENDAS'!E153 -> 23
...

Sheet UNILAB - RELATÓRIO VENDAS
A1: CENTRO MÉDICO INTEGRADO 2026
A2: RELATÓRIO CUSTOS UNILAB - RELATÓRIO DE VENDAS
A3: QTDE | B3: MNEMÔNICO | C3: PROCEDIMENTO | D3: CUSTO | E3: VENDA | F3: RECEITA | G3: LUCRO
A4: SEQUÊNCIA ALFABETICA - A
A5: 1 | B5: 25OHVITD | C5: 25-HIDROXI VITAMINA D | D5: 19.5 | E5: 34.5 | F5: =E5-D5 -> 15 | G5: =E5/D5-100% -> 0.76923077
A6: 2 | B6: ACFOL | C6: ACIDO FOLICO | D6: 28 | E6: =D6*170% -> 47.6 | F6: =E6-D6 -> 19.6 | G6: =E6/D6-100% -> 0.7
A7: 3 | B7: HIPURIJ | C7: ACIDO HIPURICO, URINA - INICIO DE JORNADA | D7: 9.9 | E7: 19 | F7: =E7-D7 -> 9.1 | G7: =E7/D7-100% -> 0.91919192
A8: 4 | B8: HIPURIS | C8: ACIDO HIPURICO, URINA ISOLADA | D8: 9.9 | E8: 19 | F8: =E8-D8 -> 9.1 | G8: =E8/D8-100% -> 0.91919192
A9: 5 | B9: METHURIS | C9: ÁCIDO METIL HIPÚRICO FINAL DE JORNADA | D9: 9.9 | E9: 19 | F9: =E9-D9 -> 9.1 | G9: =E9/D9-100% -> 0.91919192
A10: 6 | B10: AMHI | C10: ÁCIDO METIL HIPÚRICO, INÍCIO DE JORNADA | D10: 9.9 | E10: 19 | F10: =E10-D10 -> 9.1 | G10: =E10/D10-100% -> 0.91919192
A11: 7 | B11: ACUR | C11: ACIDO URICO | D11: 3 | E11: 6 | F11: =E11-D11 -> 3 | G11: =E11/D11-100% -> 1
A12: 8 | B12: ALB | C12: ALBUMINA SERICA | D12: 7 | E12: =D12*170% -> 11.9 | F12: =E12-D12 -> 4.9 | G12: =E12/D12-100% -> 0.7
A13: 9 | B13: AMIL | C13: AMILASE SERICA | D13: 4 | E13: =D13*170% -> 6.8 | F13: =E13-D13 -> 2.8 | G13: =E13/D13-100% -> 0.7
A14: 10 | B14: PSAT | C14: ANTIGENO PROSTATICO ESPECIFICO | D14: 19.85 | E14: 38 | F14: =E14-D14 -> 18.15 | G14: =E14/D14-100% -> 0.91435768
A15: 11 | C15: ANTIGENO PROSTATICO ESPECIFICO TOTAL E LIVRE | D15: 19.85 | E15: 34 | F15: =E15-D15 -> 14.15 | G15: =E15/D15-100% -> 0.71284635
A16: 12 | B16: PSATL | C16: ANTIGENO PROSTATICO ESPECIFICO TOTAL E LIVRE | D16: 25 | E16: =D16*170% -> 42.5 | F16: =E16-D16 -> 17.5 | G16: =E16/D16-100% -> 0.7
A17: SEQUÊNCIA ALFABETICA - B
A18: 13 | B18: BILI# | C18: BILIRRUBINAS TOTAL E FRAÇÕES | D18: 5 | E18: =D18*170% -> 8.5 | F18: =E18-D18 -> 3.5 | G18: =E18/D18-100% -> 0.7
A19: 14 | C19: BILIRRUBINAS TOTAL E FRAÇÕES - RECÉM NASCIDOS | D19: 5 | E19: =D19*170% -> 8.5 | F19: =E19-D19 -> 3.5 | G19: =E19/D19-100% -> 0.7
A20: 15 | B20: BRUC-IGG | C20: BRUCELOSE IgG, ANTICORPOS | D20: 28 | E20: =D20*170% -> 47.6 | F20: =E20-D20 -> 19.6 | G20: =E20/D20-100% -> 0.7
A21: 16 | B21: BRUC-IGM | C21: BRUCELOSE IGM, ANTICORPOS | D21: 28 | E21: =D21*170% -> 47.6 | F21: =E21-D21 -> 19.6 | G21: =E21/D21-100% -> 0.7
A22: SEQUÊNCIA ALFABETICA - C
A23: 17 | B23: CA125 | C23: CA 125 | D23: 37 | E23: 69 | F23: =E23-D23 -> 32 | G23: =E23/D23-100% -> 0.86486486
A24: 18 | B24: CA153 | C24: CA 15-3 | D24: 50 | E24: =D24*170% -> 85 | F24: =E24-D24 -> 35 | G24: =E24/D24-100% -> 0.7
A25: 19 | B25: CA199 | C25: CA 19-9 | D25: 50 | E25: =D25*170% -> 85 | F25: =E25-D25 -> 35 | G25: =E25/D25-100% -> 0.7
A26: 20 | B26: CA724 | C26: CA 72-4 | D26: 60 | E26: =D26*170% -> 102 | F26: =E26-D26 -> 42 | G26: =E26/D26-100% -> 0.7
A27: 21 | B27: CAIONUNI | C27: CALCIO IONICO | D27: 15 | E27: =D27*170% -> 25.5 | F27: =E27-D27 -> 10.5 | G27: =E27/D27-100% -> 0.7
A28: 22 | B28: CA | C28: CALCIO SERICO | D28: 4 | E28: 7 | F28: =E28-D28 -> 3 | G28: =E28/D28-100% -> 0.75
A29: 23 | B29: TIBC | C29: CAPACIDADE TOTAL DE COMBINAÇÃO DO FERRO | D29: 6 | E29: 11 | F29: =E29-D29 -> 5 | G29: =E29/D29-100% -> 0.83333333
A30: 24 | B30: CL | C30: CLORO | D30: 4 | E30: =D30*170% -> 6.8 | F30: =E30-D30 -> 2.8 | G30: =E30/D30-100% -> 0.7
A31: 25 | B31: COAG-UNI | C31: COAGULOGRAMA | D31: 20 | E31: =D31*170% -> 34 | F31: =E31-D31 -> 14 | G31: =E31/D31-100% -> 0.7
A32: 26 | C32: COLESTEROL TOTAL | D32: 3.15 | E32: 24.5 | F32: =E32-D32 -> 21.35 | G32: =E32/D32-100% -> 6.7777778
A33: 27 | B33: COLTF | C33: COLESTEROL TOTAL E FRAÇÕES | D33: 15.3 | E33: 58 | F33: =E33-D33 -> 42.7 | G33: =E33/D33-100% -> 2.7908497
A34: 28 | B34: COPRO | C34: COPROCULTURA | D34: 13.5 | E34: 23 | F34: =E34-D34 -> 9.5 | G34: =E34/D34-100% -> 0.7037037
A35: 29 | B35: COPROE | C35: COPROCULTURA (EMPRESAS) | D35: 13.5 | E35: 23 | F35: =E35-D35 -> 9.5 | G35: =E35/D35-100% -> 0.7037037
A36: 30 | B36: CINA-S | C36: CREATINA SERICA | D36: 22 | E36: 37.4 | F36: =E36-D36 -> 15.4 | G36: =E36/D36-100% -> 0.7
A37: 31 | B37: CRE | C37: CREATININA SERICA | D37: 2.7 | E37: 6 | F37: =E37-D37 -> 3.3 | G37: =E37/D37-100% -> 1.2222222
A38: 32 | B38: CPK | C38: CREATINO FOSFOQUINASE | D38: 7.23 | E38: 12.3 | F38: =E38-D38 -> 5.07 | G38: =E38/D38-100% -> 0.70124481
A39: 33 | C39: CREATINO FOSFOQUINASE - DILUIÇÃO | D39: 7.23 | E39: =D39*170% -> 12.291 | F39: =E39-D39 -> 5.061 | G39: =E39/D39-100% -> 0.7
A40: 34 | C40: CREATINO FOSFOQUINASE POS ESFORÇO FISICO | D40: 7.23 | E40: =D40*170% -> 12.291 | F40: =E40-D40 -> 5.061 | G40: =E40/D40-100% -> 0.7
...

Sheet UNILAB - VENDAS
A1: CENTRO MÉDICO INTEGRADO 2026
A2: UNILAB - EXAMES LABORATORIAIS
A3: QTDE | B3: MNEMÔNICO | C3: PROCEDIMENTO | D3: VENDA
A4: SEQUÊNCIA ALFABÉTICA - A
A5: 1 | B5: ACFOL | C5: ACIDO FOLICO | D5: ='UNILAB - RELATÓRIO VENDAS'!E6 -> 47.6
A6: 2 | B6: HIPURIJ | C6: ACIDO HIPURICO, URINA - INICIO DE JORNADA | D6: ='UNILAB - RELATÓRIO VENDAS'!E7 -> 19
A7: 3 | B7: HIPURIS | C7: ACIDO HIPURICO, URINA ISOLADA | D7: ='UNILAB - RELATÓRIO VENDAS'!E8 -> 19
A8: 4 | B8: METHURIS | C8: ÁCIDO METIL HIPÚRICO FINAL DE JORNADA | D8: ='UNILAB - RELATÓRIO VENDAS'!E9 -> 19
A9: 5 | B9: AMHI | C9: ÁCIDO METIL HIPÚRICO, INÍCIO DE JORNADA | D9: ='UNILAB - RELATÓRIO VENDAS'!E10 -> 19
A10: 6 | B10: ACUR | C10: ACIDO URICO | D10: ='UNILAB - RELATÓRIO VENDAS'!E11 -> 6
A11: 7 | B11: ALB | C11: ALBUMINA SERICA | D11: ='UNILAB - RELATÓRIO VENDAS'!E12 -> 11.9
A12: 8 | B12: AMIL | C12: AMILASE SERICA | D12: ='UNILAB - RELATÓRIO VENDAS'!E13 -> 6.8
A13: 9 | B13: PSAT | C13: ANTIGENO PROSTATICO ESPECIFICO | D13: ='UNILAB - RELATÓRIO VENDAS'!E14 -> 38
A14: 10 | C14: ANTIGENO PROSTATICO ESPECIFICO TOTAL E LIVRE | D14: ='UNILAB - RELATÓRIO VENDAS'!E15 -> 34
A15: 11 | B15: PSATL | C15: ANTIGENO PROSTATICO ESPECIFICO TOTAL E LIVRE | D15: ='UNILAB - RELATÓRIO VENDAS'!E16 -> 42.5
A16: SEQUÊNCIA ALFABÉTICA - B
A17: 12 | B17: BILI# | C17: BILIRRUBINAS TOTAL E FRAÇÕES | D17: ='UNILAB - RELATÓRIO VENDAS'!E18 -> 8.5
A18: 13 | C18: BILIRRUBINAS TOTAL E FRAÇÕES - RECÉM NASCIDOS | D18: ='UNILAB - RELATÓRIO VENDAS'!E19 -> 8.5
A19: 14 | B19: BRUC-IGG | C19: BRUCELOSE IgG, ANTICORPOS | D19: ='UNILAB - RELATÓRIO VENDAS'!E20 -> 47.6
A20: 15 | B20: BRUC-IGM | C20: BRUCELOSE IGM, ANTICORPOS | D20: ='UNILAB - RELATÓRIO VENDAS'!E21 -> 47.6
A21: SEQUÊNCIA ALFABÉTICA - C
A22: 16 | B22: CA125 | C22: CA 125 | D22: ='UNILAB - RELATÓRIO VENDAS'!E23 -> 69
A23: 17 | B23: CA153 | C23: CA 15-3 | D23: ='UNILAB - RELATÓRIO VENDAS'!E24 -> 85
A24: 18 | B24: CA199 | C24: CA 19-9 | D24: ='UNILAB - RELATÓRIO VENDAS'!E25 -> 85
A25: 19 | B25: CA724 | C25: CA 72-4 | D25: ='UNILAB - RELATÓRIO VENDAS'!E26 -> 102
A26: 20 | B26: CAIONUNI | C26: CALCIO IONICO | D26: ='UNILAB - RELATÓRIO VENDAS'!E27 -> 25.5
A27: 21 | B27: CA | C27: CALCIO SERICO | D27: ='UNILAB - RELATÓRIO VENDAS'!E28 -> 7
A28: 22 | B28: TIBC | C28: CAPACIDADE TOTAL DE COMBINAÇÃO DO FERRO | D28: ='UNILAB - RELATÓRIO VENDAS'!E29 -> 11
A29: 23 | B29: CL | C29: CLORO | D29: ='UNILAB - RELATÓRIO VENDAS'!E30 -> 6.8
A30: 24 | B30: COAG-UNI | C30: COAGULOGRAMA | D30: ='UNILAB - RELATÓRIO VENDAS'!E31 -> 34
A31: 25 | C31: COLESTEROL TOTAL | D31: ='UNILAB - RELATÓRIO VENDAS'!E32 -> 24.5
A32: 26 | B32: COLTF | C32: COLESTEROL TOTAL E FRAÇÕES | D32: ='UNILAB - RELATÓRIO VENDAS'!E33 -> 58
A33: 27 | B33: COPRO | C33: COPROCULTURA | D33: ='UNILAB - RELATÓRIO VENDAS'!E34 -> 23
A34: 28 | B34: COPROE | C34: COPROCULTURA (EMPRESAS) | D34: ='UNILAB - RELATÓRIO VENDAS'!E35 -> 23
A35: 29 | B35: CINA-S | C35: CREATINA SERICA | D35: ='UNILAB - RELATÓRIO VENDAS'!E36 -> 37.4
A36: 30 | B36: CRE | C36: CREATININA SERICA | D36: ='UNILAB - RELATÓRIO VENDAS'!E37 -> 6
A37: 31 | B37: CPK | C37: CREATINO FOSFOQUINASE | D37: ='UNILAB - RELATÓRIO VENDAS'!E38 -> 12.3
A38: 32 | C38: CREATINO FOSFOQUINASE - DILUIÇÃO | D38: ='UNILAB - RELATÓRIO VENDAS'!E39 -> 12.291
A39: 33 | C39: CREATINO FOSFOQUINASE POS ESFORÇO FISICO | D39: ='UNILAB - RELATÓRIO VENDAS'!E40 -> 12.291
A40: 34 | B40: CR | C40: CROMO SERICO | D40: ='UNILAB - RELATÓRIO VENDAS'!E41 -> 45
...
